2025-02-01 03:12:50,102 DEBUG    root            Loaded Command Group: ['gcloud', 'config']
2025-02-01 03:12:50,103 DEBUG    root            Loaded Command Group: ['gcloud', 'config', 'config_helper']
2025-02-01 03:12:50,104 DEBUG    root            Running [gcloud.config.config-helper] with arguments: [--format: "json", --min-expiry: "3600"]
2025-02-01 03:30:32,115 DEBUG    google.auth.transport.requests Making request: POST https://oauth2.googleapis.com/token
2025-02-01 03:31:02,131 DEBUG    urllib3.connectionpool Starting new HTTPS connection (1): oauth2.googleapis.com:443
2025-02-01 03:31:32,138 DEBUG    google.auth.transport.requests Making request: POST https://oauth2.googleapis.com/token
2025-02-01 03:32:02,146 DEBUG    urllib3.connectionpool Starting new HTTPS connection (2): oauth2.googleapis.com:443
2025-02-01 03:49:58,140 DEBUG    root            (gcloud.config.config-helper) There was a problem refreshing your current auth tokens: HTTPSConnectionPool(host='oauth2.googleapis.com', port=443): Max retries exceeded with url: /token (Caused by NewConnectionError('<urllib3.connection.HTTPSConnection object at 0x107bf29d0>: Failed to establish a new connection: [Errno 8] nodename nor servname provided, or not known'))
Please run:

  $ gcloud auth login

to obtain new credentials.

If you have already logged in with a different account, run:

  $ gcloud config set account ACCOUNT

to select an already authenticated account to use.
Traceback (most recent call last):
  File "/Users/tamjid/google-cloud-sdk/lib/third_party/urllib3/connection.py", line 174, in _new_conn
    conn = connection.create_connection(
           ^^^^^^^^^^^^^^^^^^^^^^^^^^^^^
  File "/Users/tamjid/google-cloud-sdk/lib/third_party/urllib3/util/connection.py", line 72, in create_connection
    for res in socket.getaddrinfo(host, port, family, socket.SOCK_STREAM):
               ^^^^^^^^^^^^^^^^^^^^^^^^^^^^^^^^^^^^^^^^^^^^^^^^^^^^^^^^^^
  File "/Library/Frameworks/Python.framework/Versions/3.11/lib/python3.11/socket.py", line 962, in getaddrinfo
    for res in _socket.getaddrinfo(host, port, family, type, proto, flags):
               ^^^^^^^^^^^^^^^^^^^^^^^^^^^^^^^^^^^^^^^^^^^^^^^^^^^^^^^^^^^
socket.gaierror: [Errno 8] nodename nor servname provided, or not known

During handling of the above exception, another exception occurred:

Traceback (most recent call last):
  File "/Users/tamjid/google-cloud-sdk/lib/third_party/urllib3/connectionpool.py", line 717, in urlopen
    httplib_response = self._make_request(
                       ^^^^^^^^^^^^^^^^^^^
  File "/Users/tamjid/google-cloud-sdk/lib/third_party/urllib3/connectionpool.py", line 406, in _make_request
    self._validate_conn(conn)
  File "/Users/tamjid/google-cloud-sdk/lib/third_party/urllib3/connectionpool.py", line 1057, in _validate_conn
    conn.connect()
  File "/Users/tamjid/google-cloud-sdk/lib/third_party/urllib3/connection.py", line 358, in connect
    self.sock = conn = self._new_conn()
                       ^^^^^^^^^^^^^^^^
  File "/Users/tamjid/google-cloud-sdk/lib/third_party/urllib3/connection.py", line 186, in _new_conn
    raise NewConnectionError(
urllib3.exceptions.NewConnectionError: <urllib3.connection.HTTPSConnection object at 0x107bf29d0>: Failed to establish a new connection: [Errno 8] nodename nor servname provided, or not known

During handling of the above exception, another exception occurred:

Traceback (most recent call last):
  File "/Users/tamjid/google-cloud-sdk/lib/third_party/requests/adapters.py", line 439, in send
    resp = conn.urlopen(
           ^^^^^^^^^^^^^
  File "/Users/tamjid/google-cloud-sdk/lib/third_party/urllib3/connectionpool.py", line 799, in urlopen
    retries = retries.increment(
              ^^^^^^^^^^^^^^^^^^
  File "/Users/tamjid/google-cloud-sdk/lib/third_party/urllib3/util/retry.py", line 592, in increment
    raise MaxRetryError(_pool, url, error or ResponseError(cause))
urllib3.exceptions.MaxRetryError: HTTPSConnectionPool(host='oauth2.googleapis.com', port=443): Max retries exceeded with url: /token (Caused by NewConnectionError('<urllib3.connection.HTTPSConnection object at 0x107bf29d0>: Failed to establish a new connection: [Errno 8] nodename nor servname provided, or not known'))

During handling of the above exception, another exception occurred:

Traceback (most recent call last):
  File "/Users/tamjid/google-cloud-sdk/lib/third_party/google/auth/transport/requests.py", line 186, in __call__
    response = self.session.request(
               ^^^^^^^^^^^^^^^^^^^^^
  File "/Users/tamjid/google-cloud-sdk/lib/googlecloudsdk/core/transport.py", line 269, in WrappedRequest
    response = orig_request(*modified_args, **modified_kwargs)
               ^^^^^^^^^^^^^^^^^^^^^^^^^^^^^^^^^^^^^^^^^^^^^^^
  File "/Users/tamjid/google-cloud-sdk/lib/googlecloudsdk/core/requests.py", line 246, in WrappedRequest
    return orig_request_method(*args, **kwargs)
           ^^^^^^^^^^^^^^^^^^^^^^^^^^^^^^^^^^^^
  File "/Users/tamjid/google-cloud-sdk/lib/third_party/requests/sessions.py", line 544, in request
    resp = self.send(prep, **send_kwargs)
           ^^^^^^^^^^^^^^^^^^^^^^^^^^^^^^
  File "/Users/tamjid/google-cloud-sdk/lib/third_party/requests/sessions.py", line 657, in send
    r = adapter.send(request, **kwargs)
        ^^^^^^^^^^^^^^^^^^^^^^^^^^^^^^^
  File "/Users/tamjid/google-cloud-sdk/lib/third_party/requests/adapters.py", line 516, in send
    raise ConnectionError(e, request=request)
requests.exceptions.ConnectionError: HTTPSConnectionPool(host='oauth2.googleapis.com', port=443): Max retries exceeded with url: /token (Caused by NewConnectionError('<urllib3.connection.HTTPSConnection object at 0x107bf29d0>: Failed to establish a new connection: [Errno 8] nodename nor servname provided, or not known'))

The above exception was the direct cause of the following exception:

Traceback (most recent call last):
  File "/Users/tamjid/google-cloud-sdk/lib/googlecloudsdk/calliope/cli.py", line 998, in Execute
    resources = calliope_command.Run(cli=self, args=args)
                ^^^^^^^^^^^^^^^^^^^^^^^^^^^^^^^^^^^^^^^^^
  File "/Users/tamjid/google-cloud-sdk/lib/googlecloudsdk/calliope/backend.py", line 815, in Run
    resources = command_instance.Run(args)
                ^^^^^^^^^^^^^^^^^^^^^^^^^^
  File "/Users/tamjid/google-cloud-sdk/lib/surface/config/config_helper.py", line 99, in Run
    cred = store.Load(use_google_auth=True)
           ^^^^^^^^^^^^^^^^^^^^^^^^^^^^^^^^
  File "/Users/tamjid/google-cloud-sdk/lib/googlecloudsdk/core/credentials/store.py", line 746, in Load
    cred = _Load(
           ^^^^^^
  File "/Users/tamjid/google-cloud-sdk/lib/googlecloudsdk/core/credentials/store.py", line 958, in _Load
    RefreshIfAlmostExpire(cred)
  File "/Users/tamjid/google-cloud-sdk/lib/googlecloudsdk/core/credentials/store.py", line 1302, in RefreshIfAlmostExpire
    RefreshIfExpireWithinWindow(credentials, window=_CREDENTIALS_EXPIRY_WINDOW)
  File "/Users/tamjid/google-cloud-sdk/lib/googlecloudsdk/core/credentials/store.py", line 1298, in RefreshIfExpireWithinWindow
    Refresh(credentials)
  File "/Users/tamjid/google-cloud-sdk/lib/googlecloudsdk/core/credentials/store.py", line 998, in Refresh
    _RefreshGoogleAuth(credentials, is_impersonated_credential,
  File "/Users/tamjid/google-cloud-sdk/lib/googlecloudsdk/core/credentials/store.py", line 1189, in _RefreshGoogleAuth
    credentials.refresh(request_client)
  File "/Users/tamjid/google-cloud-sdk/lib/googlecloudsdk/core/credentials/creds.py", line 943, in _WrappedRefresh
    orig_refresh(request)
  File "/Users/tamjid/google-cloud-sdk/lib/googlecloudsdk/core/credentials/google_auth_credentials.py", line 105, in refresh
    return self._Refresh(request)
           ^^^^^^^^^^^^^^^^^^^^^^
  File "/Users/tamjid/google-cloud-sdk/lib/googlecloudsdk/core/credentials/google_auth_credentials.py", line 167, in _Refresh
    access_token, refresh_token, expiry, grant_response = _RefreshGrant(
                                                          ^^^^^^^^^^^^^^
  File "/Users/tamjid/google-cloud-sdk/lib/googlecloudsdk/core/credentials/google_auth_credentials.py", line 262, in _RefreshGrant
    response_data = _TokenEndpointRequestWithRetry(request, token_uri, body)
                    ^^^^^^^^^^^^^^^^^^^^^^^^^^^^^^^^^^^^^^^^^^^^^^^^^^^^^^^^
  File "/Users/tamjid/google-cloud-sdk/lib/googlecloudsdk/core/util/retry.py", line 312, in DecoratedFunction
    exceptions.reraise(to_reraise[1], tb=to_reraise[2])
  File "/Users/tamjid/google-cloud-sdk/lib/googlecloudsdk/core/exceptions.py", line 149, in reraise
    six.reraise(type(exc_value), exc_value, tb)
  File "/Users/tamjid/google-cloud-sdk/lib/third_party/six/__init__.py", line 719, in reraise
    raise value
  File "/Users/tamjid/google-cloud-sdk/lib/googlecloudsdk/core/util/retry.py", line 182, in TryFunc
    return func(*args, **kwargs), None
           ^^^^^^^^^^^^^^^^^^^^^
  File "/Users/tamjid/google-cloud-sdk/lib/googlecloudsdk/core/credentials/google_auth_credentials.py", line 318, in _TokenEndpointRequestWithRetry
    response = request(method='POST', url=token_uri, headers=headers, body=body)
               ^^^^^^^^^^^^^^^^^^^^^^^^^^^^^^^^^^^^^^^^^^^^^^^^^^^^^^^^^^^^^^^^^
  File "/Users/tamjid/google-cloud-sdk/lib/third_party/google/auth/transport/requests.py", line 192, in __call__
    raise new_exc from caught_exc
google.auth.exceptions.TransportError: HTTPSConnectionPool(host='oauth2.googleapis.com', port=443): Max retries exceeded with url: /token (Caused by NewConnectionError('<urllib3.connection.HTTPSConnection object at 0x107bf29d0>: Failed to establish a new connection: [Errno 8] nodename nor servname provided, or not known'))
2025-02-01 03:49:58,151 ERROR    root            (gcloud.config.config-helper) There was a problem refreshing your current auth tokens: HTTPSConnectionPool(host='oauth2.googleapis.com', port=443): Max retries exceeded with url: /token (Caused by NewConnectionError('<urllib3.connection.HTTPSConnection object at 0x107bf29d0>: Failed to establish a new connection: [Errno 8] nodename nor servname provided, or not known'))
Please run:

  $ gcloud auth login

to obtain new credentials.

If you have already logged in with a different account, run:

  $ gcloud config set account ACCOUNT

to select an already authenticated account to use.
